2024-05-18 22:20:22 ERROR Traceback (most recent call last):
  File "/Data/harold.ngoupeyou/cheese_challenge/lib/python3.10/site-packages/wandb/apis/normalize.py", line 41, in wrapper
    return func(*args, **kwargs)
  File "/Data/harold.ngoupeyou/cheese_challenge/lib/python3.10/site-packages/wandb/sdk/internal/internal_api.py", line 1036, in sweep
    raise ValueError(f"Sweep {entity}/{project}/{sweep} not found")
ValueError: Sweep harold/cheese_challenge/itrwns68 not found

During handling of the above exception, another exception occurred:

Traceback (most recent call last):
  File "/Data/harold.ngoupeyou/cheese_challenge/lib/python3.10/site-packages/wandb/cli/cli.py", line 108, in wrapper
    return func(*args, **kwargs)
  File "/Data/harold.ngoupeyou/cheese_challenge/lib/python3.10/site-packages/wandb/cli/cli.py", line 930, in sweep
    getattr(api, "%s_sweep" % state)(sweep_id, entity=entity, project=project)
  File "/Data/harold.ngoupeyou/cheese_challenge/lib/python3.10/site-packages/wandb/apis/internal.py", line 144, in pause_sweep
    return self.api.pause_sweep(*args, **kwargs)
  File "/Data/harold.ngoupeyou/cheese_challenge/lib/python3.10/site-packages/wandb/sdk/internal/internal_api.py", line 4020, in pause_sweep
    self.set_sweep_state(
  File "/Data/harold.ngoupeyou/cheese_challenge/lib/python3.10/site-packages/wandb/sdk/internal/internal_api.py", line 3953, in set_sweep_state
    s = self.sweep(sweep=sweep, entity=entity, project=project, specs="{}")
  File "/Data/harold.ngoupeyou/cheese_challenge/lib/python3.10/site-packages/wandb/apis/normalize.py", line 87, in wrapper
    raise CommError(message, err).with_traceback(sys.exc_info()[2])
  File "/Data/harold.ngoupeyou/cheese_challenge/lib/python3.10/site-packages/wandb/apis/normalize.py", line 41, in wrapper
    return func(*args, **kwargs)
  File "/Data/harold.ngoupeyou/cheese_challenge/lib/python3.10/site-packages/wandb/sdk/internal/internal_api.py", line 1036, in sweep
    raise ValueError(f"Sweep {entity}/{project}/{sweep} not found")
wandb.errors.CommError: Sweep harold/cheese_challenge/itrwns68 not found

2024-05-18 22:20:40 ERROR Traceback (most recent call last):
  File "/Data/harold.ngoupeyou/cheese_challenge/lib/python3.10/site-packages/wandb/apis/normalize.py", line 41, in wrapper
    return func(*args, **kwargs)
  File "/Data/harold.ngoupeyou/cheese_challenge/lib/python3.10/site-packages/wandb/sdk/internal/internal_api.py", line 1036, in sweep
    raise ValueError(f"Sweep {entity}/{project}/{sweep} not found")
ValueError: Sweep haroldng/cheese_challenge/itrwns68 not found

During handling of the above exception, another exception occurred:

Traceback (most recent call last):
  File "/Data/harold.ngoupeyou/cheese_challenge/lib/python3.10/site-packages/wandb/cli/cli.py", line 108, in wrapper
    return func(*args, **kwargs)
  File "/Data/harold.ngoupeyou/cheese_challenge/lib/python3.10/site-packages/wandb/cli/cli.py", line 930, in sweep
    getattr(api, "%s_sweep" % state)(sweep_id, entity=entity, project=project)
  File "/Data/harold.ngoupeyou/cheese_challenge/lib/python3.10/site-packages/wandb/apis/internal.py", line 144, in pause_sweep
    return self.api.pause_sweep(*args, **kwargs)
  File "/Data/harold.ngoupeyou/cheese_challenge/lib/python3.10/site-packages/wandb/sdk/internal/internal_api.py", line 4020, in pause_sweep
    self.set_sweep_state(
  File "/Data/harold.ngoupeyou/cheese_challenge/lib/python3.10/site-packages/wandb/sdk/internal/internal_api.py", line 3953, in set_sweep_state
    s = self.sweep(sweep=sweep, entity=entity, project=project, specs="{}")
  File "/Data/harold.ngoupeyou/cheese_challenge/lib/python3.10/site-packages/wandb/apis/normalize.py", line 87, in wrapper
    raise CommError(message, err).with_traceback(sys.exc_info()[2])
  File "/Data/harold.ngoupeyou/cheese_challenge/lib/python3.10/site-packages/wandb/apis/normalize.py", line 41, in wrapper
    return func(*args, **kwargs)
  File "/Data/harold.ngoupeyou/cheese_challenge/lib/python3.10/site-packages/wandb/sdk/internal/internal_api.py", line 1036, in sweep
    raise ValueError(f"Sweep {entity}/{project}/{sweep} not found")
wandb.errors.CommError: Sweep haroldng/cheese_challenge/itrwns68 not found

